2022-07-11 16:33:41,563 INFO    MainThread:4068667 [internal.py:wandb_internal():90] W&B internal server running at pid: 4068667, started at: 2022-07-11 16:33:41.562978
2022-07-11 16:33:41,564 INFO    WriterThread:4068667 [datastore.py:open_for_write():75] open: /home/ingu627/kisti/wandb_ex/wandb/run-20220711_163340-394q6mh4/run-394q6mh4.wandb
2022-07-11 16:33:41,565 DEBUG   SenderThread:4068667 [sender.py:send():235] send: header
2022-07-11 16:33:41,565 DEBUG   SenderThread:4068667 [sender.py:send():235] send: run
2022-07-11 16:33:41,776 ERROR   SenderThread:4068667 [internal_api.py:execute():143] 404 response executing GraphQL.
2022-07-11 16:33:41,776 ERROR   SenderThread:4068667 [internal_api.py:execute():144] {"errors":[{"message":"entity poeun not found during upsertBucket","path":["upsertBucket"]}],"data":{"upsertBucket":null}}
2022-07-11 16:33:42,564 INFO    WriterThread:4068667 [datastore.py:close():279] close: /home/ingu627/kisti/wandb_ex/wandb/run-20220711_163340-394q6mh4/run-394q6mh4.wandb
2022-07-11 16:33:42,565 INFO    HandlerThread:4068667 [handler.py:finish():806] shutting down handler
2022-07-11 16:33:42,565 ERROR   MainThread:4068667 [internal.py:wandb_internal():165] Thread SenderThread:
Traceback (most recent call last):
  File "/home/ingu627/gtx2080/lib/python3.8/site-packages/wandb/sdk/lib/retry.py", line 108, in __call__
    result = self._call_fn(*args, **kwargs)
  File "/home/ingu627/gtx2080/lib/python3.8/site-packages/wandb/sdk/internal/internal_api.py", line 140, in execute
    return self.client.execute(*args, **kwargs)
  File "/home/ingu627/gtx2080/lib/python3.8/site-packages/wandb/vendor/gql-0.2.0/wandb_gql/client.py", line 52, in execute
    result = self._get_result(document, *args, **kwargs)
  File "/home/ingu627/gtx2080/lib/python3.8/site-packages/wandb/vendor/gql-0.2.0/wandb_gql/client.py", line 60, in _get_result
    return self.transport.execute(document, *args, **kwargs)
  File "/home/ingu627/gtx2080/lib/python3.8/site-packages/wandb/vendor/gql-0.2.0/wandb_gql/transport/requests.py", line 39, in execute
    request.raise_for_status()
  File "/home/ingu627/gtx2080/lib/python3.8/site-packages/requests/models.py", line 960, in raise_for_status
    raise HTTPError(http_error_msg, response=self)
requests.exceptions.HTTPError: 404 Client Error: Not Found for url: https://api.wandb.ai/graphql

During handling of the above exception, another exception occurred:

Traceback (most recent call last):
  File "/home/ingu627/gtx2080/lib/python3.8/site-packages/wandb/apis/normalize.py", line 22, in wrapper
    return func(*args, **kwargs)
  File "/home/ingu627/gtx2080/lib/python3.8/site-packages/wandb/sdk/internal/internal_api.py", line 1319, in upsert_run
    response = self.gql(mutation, variable_values=variable_values, **kwargs)
  File "/home/ingu627/gtx2080/lib/python3.8/site-packages/wandb/sdk/lib/retry.py", line 124, in __call__
    if not check_retry_fn(e):
  File "/home/ingu627/gtx2080/lib/python3.8/site-packages/wandb/util.py", line 887, in no_retry_auth
    raise CommError("Permission denied, ask the project owner to grant you access")
wandb.errors.CommError: Permission denied, ask the project owner to grant you access

During handling of the above exception, another exception occurred:

Traceback (most recent call last):
  File "/home/ingu627/gtx2080/lib/python3.8/site-packages/wandb/sdk/internal/internal_util.py", line 51, in run
    self._run()
  File "/home/ingu627/gtx2080/lib/python3.8/site-packages/wandb/sdk/internal/internal_util.py", line 102, in _run
    self._process(record)
  File "/home/ingu627/gtx2080/lib/python3.8/site-packages/wandb/sdk/internal/internal.py", line 310, in _process
    self._sm.send(record)
  File "/home/ingu627/gtx2080/lib/python3.8/site-packages/wandb/sdk/internal/sender.py", line 237, in send
    send_handler(record)
  File "/home/ingu627/gtx2080/lib/python3.8/site-packages/wandb/sdk/internal/sender.py", line 695, in send_run
    self._init_run(run, config_value_dict)
  File "/home/ingu627/gtx2080/lib/python3.8/site-packages/wandb/sdk/internal/sender.py", line 719, in _init_run
    server_run, inserted = self._api.upsert_run(
  File "/home/ingu627/gtx2080/lib/python3.8/site-packages/wandb/apis/normalize.py", line 58, in wrapper
    raise CommError(message, err).with_traceback(sys.exc_info()[2])
  File "/home/ingu627/gtx2080/lib/python3.8/site-packages/wandb/apis/normalize.py", line 22, in wrapper
    return func(*args, **kwargs)
  File "/home/ingu627/gtx2080/lib/python3.8/site-packages/wandb/sdk/internal/internal_api.py", line 1319, in upsert_run
    response = self.gql(mutation, variable_values=variable_values, **kwargs)
  File "/home/ingu627/gtx2080/lib/python3.8/site-packages/wandb/sdk/lib/retry.py", line 124, in __call__
    if not check_retry_fn(e):
  File "/home/ingu627/gtx2080/lib/python3.8/site-packages/wandb/util.py", line 887, in no_retry_auth
    raise CommError("Permission denied, ask the project owner to grant you access")
wandb.errors.CommError: Permission denied, ask the project owner to grant you access
2022-07-11 16:33:44,106 INFO    MainThread:4068667 [internal.py:handle_exit():80] Internal process exited
